[2025-07-23 02:14:18] ERROR [django.request:248] Internal Server Error: /photography/
Traceback (most recent call last):
  File "C:\Users\NUWAA\AppData\Local\Programs\Python\Python313\Lib\site-packages\django\core\handlers\exception.py", line 55, in inner
    response = get_response(request)
  File "C:\Users\NUWAA\AppData\Local\Programs\Python\Python313\Lib\site-packages\django\core\handlers\base.py", line 197, in _get_response
    response = wrapped_callback(request, *callback_args, **callback_kwargs)
  File "C:\Users\NUWAA\PycharmProjects\nuwanga_rajapaksha_v1\photography\views.py", line 24, in photography
    'tech_icons_row1': tech_icons_row1,
                       ^^^^^^^^^^^^^^^
NameError: name 'tech_icons_row1' is not defined. Did you mean: 'tech_icons_row3'?
[2025-07-23 02:14:18] ERROR [django.server:213] "GET /photography/ HTTP/1.1" 500 73412
[2025-07-23 02:19:28] WARNING [django.server:213] "GET /static/icons/nikon-d7200.jpg HTTP/1.1" 404 1877
[2025-07-23 02:19:28] WARNING [django.server:213] "GET /static/icons/nikon-18-55.png HTTP/1.1" 404 1877
[2025-07-23 02:19:39] WARNING [django.server:213] "GET /static/icons/nikon-d7200.jpg HTTP/1.1" 404 1877
[2025-07-23 02:19:39] WARNING [django.server:213] "GET /static/icons/nikon-18-55.png HTTP/1.1" 404 1877
[2025-07-23 02:20:27] WARNING [django.server:213] "GET /static/icons/nikon-18-55.png HTTP/1.1" 404 1877
[2025-07-23 02:20:27] WARNING [django.server:213] "GET /static/icons/nikon-d7200.jpg HTTP/1.1" 404 1877
[2025-07-23 02:20:36] WARNING [django.server:213] "GET /static/icons/nikon-d7200.jpg HTTP/1.1" 404 1877
[2025-07-23 02:20:36] WARNING [django.server:213] "GET /static/icons/nikon-18-55.png HTTP/1.1" 404 1877
